Workbook

Sheet strona tytułowa
A5: Analiza sprawozdań finansowych spółki OPTeam S.A. za lata 2022, 2023, 2024
A37: Szymon Łukasik | H37: Adam Marko

Sheet wprowadzenie
A1: OPTeam S.A. to firma ulokowana w Tajęcinie koło Rzeszowa. Jest lokalnym graczem w sektorze IT pod obecną nazwą od 2003 roku. Na GPW widnieje od roku 2010. Firma specjalizuje się we wdrażaniu nowoczesnych rozwiązań informatycznych tj. płatności, systemy ERP dla sektora publicznego, przedsiębiorstw oraz uczelni wyższych.

Sheet RZIS & CASHFLOW & BILANS
C3: AKTYWA | D3: Stan na 31.12.2022 | E3: Stan na 31.12.2023 | F3: Stan na 31.12.2024 | H3: Stan na 31.12.2021 r.
C5: A. Aktywa trwałe | D5: 31211272 | E5: 30390474 | F5: ='RZIS & CASHFLOW & BILANS'!D84*2*100 -> -404176910 | H5: 27305928
C6: 1. Wartość firmy | D6: 184193.99 | E6: 184193.99 | F6: 184193.99 | H6: 184193.99
C7: 2. Inne wartości niematerialne | D7: 4446486.5 | E7: 4406627.9 | F7: 8500781.2 | H7: 2266616.3
C8: 3. Rzeczowe aktywa trwałe | D8: 16237944 | E8: 15044999 | F8: 14156555 | H8: 16531623
C9: 4. Nieruchomości inwestycyjne | D9: - | E9: - | F9: - | H9: —
C10: 5. Należności długoterminowe | D10: 42602.34 | E10: 881125.73 | F10: 410947.73 | H10: —
C11: 6. Inwestycje w jednostkach podporządkowanych | D11: 8376521 | E11: 8498239 | F11: 0 | H11: 7399448.3
C12: 7. Aktywa finansowe | D12: 400000 | E12: 400000 | F12: 400000 | H12: 400000
C13: 8. Aktywa z tytułu podatku odroczonego | D13: 1523524 | E13: 975287.92 | F13: 657728.27 | H13: 524045.77
C14: 9. Inne rozliczenia międzyokresowe | D14: - | E14: - | F14: - | H14: —
C15: B. Aktywa obrotowe | D15: 40951220 | E15: 41135074 | F15: 27995585 | H15: 60400462
C16: 1. Zapasy | D16: 2912656.1 | E16: 1535369.1 | F16: 1522500.1 | H16: 1632443.9
C17: 2. Należności z tytułu dostaw i usług | D17: 18142688 | E17: 12390084 | F17: 14492916 | H17: 22301078
C18: 3. Aktywa z tytułu umów z klientami | D18: 3124218.4 | E18: 2267227.2 | F18: 3207419.3 | H18: 2146567.7
C19: 4. Należności pozostałe | D19: 116295 | E19: 57104.25 | F19: 363887.9 | H19: 50942.75
C20: 5. Należności z tytułu podatku dochodowego od osób prawnych | D20: - | E20: - | F20: - | H20: 281351
C21: 6. Należności z tytułu pozostałych podatków, dotacji, ceł, ubezpieczeń | D21: 277813.45 | E21: 271073 | F21: 203760.13 | H21: 244930.78
C22: 7. Aktywa finansowe | D22: 12281000 | E22: 4652656 | F22: 0 | H22: 30000000
C23: 8. Środki pieniężne i ich ekwiwalenty | D23: 3517220 | E23: 19392444 | F23: 7518226.3 | H23: 3406348.6
C24: 9. Rozliczenia międzyokresowe | D24: 579328.85 | E24: 569115.9 | F24: 686876.21 | H24: 336799.45
C25: C. Aktywa przeznaczone do zbycia | D25: - | E25: - | F25: - | H25: —
C26: RAZEM AKTYWA | D26: 72162491 | E26: 71525548 | F26: 52305792 | H26: 87706390
C30: PASYWA | D30: 2022 | E30: 2023 | F30: 2024
C32: A. Kapitał własny | D32: 47711738 | E32: 47948669 | F32: 30865442
C33: 1. Kapitał akcyjny | D33: 787150 | E33: 787150 | F33: 787150
C34: 2. Akcje własne (wielkość ujemna) | D34: -1095.46 | E34: -1095.46 | F34: -1095.46
C35: 3. Kapitał zapasowy | D35: 47965952 | E35: 45945067 | F35: 39357660
C36: 4. Kapitał rezerwowy | D36: 980616.16 | E36: 980616.16 | F36: 980616.16
C37: 5. Zysk (strata) z lat ubiegłych | D37: - | E37: - | F37: -
C38: 6. Zyski (strata) netto | D38: -2020884.6 | E38: 236930.71 | F38: -10258889
C39: 7. Odpisy z zysku netto w ciągu roku obrotowego | D39: - | E39: - | F39: -
C40: B. Zobowiązania długoterminowe | D40: 5962098 | E40: 5704757.4 | F40: 5385567
C41: 1. Kredyty bankowe | D41: - | E41: - | F41: -
C42: 2. Zobowiązania finansowe | D42: 17880.63 | E42: - | F42: -
C43: 3. Zobowiązania z tytułu dostaw i usług | D43: - | E43: - | F43: -
C44: 4. Zobowiązania pozostałe | D44: - | E44: - | F44: 7195.5
C45: 5. Rezerwa z tytułu podatku odroczonego | D45: 780401.37 | E45: 757129.71 | F45: 852925.93
C46: 6. Rezerwy na inne zobowiązania | D46: 112389.85 | E46: 140058 | F46: 150382
C47: 7. Rozliczenia międzyokresowe | D47: 5051426.2 | E47: 4807569.7 | F47: 4375063.5
...

Sheet Analiza Wstepna
A1: Analiza Pozioma
A2: ELEMENTY BILANSU | B2: 2022 | C2: 2023 | D2: 2024 | E2: ZMIANA BEZW. 22-23 | F2: ZMIANA BEZW. 23-24 | G2: TEMPO ZMIAN 2022-23 | H2: TEAMPO ZMIAN 2023-24 | I2: WSKAŹ. DYNAMIKI 22-23 | J2: WSKAŹ DYNAMIKI 23-24
A3: A. Aktywa trwałe | B3: 31211272 | C3: 30390474 | D3: 24310206 | E3: =C3-B3 -> -820798.22 | F3: =D3-C3 -> -6080267.6 | G3: =E3/B3 -> -0.026298134 | H3: =F3/C3 -> -0.2000715 | I3: =C3/B3 -> 0.97370187 | J3: =D3/C3 -> 0.7999285
A4: B. Aktywa obrotowe | B4: 40951220 | C4: 41135074 | D4: 27995585 | E4: =C4-B4 -> 183854.61 | F4: =D4-C4 -> -13139489 | G4: =E4/B4 -> 0.0044896004 | H4: =F4/C4 -> -0.319423 | I4: =C4/B4 -> 1.0044896 | J4: =D4/C4 -> 0.680577
A5: RAZEM AKTYWA | B5: 72162491 | C5: 71525548 | D5: 52305792 | E5: =C5-B5 -> -636943.61 | F5: =D5-C5 -> -19219756 | G5: =E5/B5 -> -0.0088265191 | H5: =F5/C5 -> -0.26871177 | I5: =C5/B5 -> 0.99117348 | J5: =D5/C5 -> 0.73128823
A6: A. Kapitał własny | B6: 47711738 | C6: 47948669 | D6: 30865442 | E6: =C6-B6 -> 236930.71 | F6: =D6-C6 -> -17083227 | G6: =E6/B6 -> 0.0049658788 | H6: =F6/C6 -> -0.35628157 | I6: =C6/B6 -> 1.0049659 | J6: =D6/C6 -> 0.64371843
A7: B. Zobowiązania długoterminowe | B7: 5962098 | C7: 5704757.4 | D7: 5385567 | E7: =C7-B7 -> -257340.58 | F7: =D7-C7 -> -319190.46 | G7: =E7/B7 -> -0.043162756 | H7: =F7/C7 -> -0.055951627 | I7: =C7/B7 -> 0.95683724 | J7: =D7/C7 -> 0.94404837
A8: C. Zobowiązania krótkoterminowe | B8: 18488655 | C8: 17872122 | D8: 16054783 | E8: =C8-B8 -> -616533.74 | F8: =D8-C8 -> -1817338.9 | G8: =E8/B8 -> -0.033346597 | H8: =F8/C8 -> -0.10168568 | I8: =C8/B8 -> 0.9666534 | J8: =D8/C8 -> 0.89831432
A9: RAZEM PASYWA | B9: 72162491 | C9: 71525548 | D9: 52305792 | E9: =C9-B9 -> -636943.61 | F9: =D9-C9 -> -19219756 | G9: =E9/B9 -> -0.0088265191 | H9: =F9/C9 -> -0.26871177 | I9: =C9/B9 -> 0.99117348 | J9: =D9/C9 -> 0.73128823
A10: ELEMENTY RZIS | B10: 2022 | C10: 2023 | D10: 2024 | E10: ZMIANA BEZW. 22-23 | F10: ZMIANA BEZW. 23-24 | G10: TEMPO ZMIAN 2022-23 | H10: TEAMPO ZMIAN 2023-24 | I10: WSKAŹ. DYNAMIKI 22-23 | J10: WSKAŹ DYNAMIKI 23-24
A11: I. Przychody ze sprzedaży produktów, towarów i materiałów, w tym: | B11: 85736591 | C11: 90843657 | D11: 70301360 | E11: =C11-B11 -> 5107065.9 | F11: =D11-C11 -> -20542296 | G11: =E11/B11 -> 0.059566934 | H11: =F11/C11 -> -0.22612802 | I11: =C11/B11 -> 1.0595669 | J11: =D11/C11 -> 0.77387198
A12: II. Koszty sprzedanych produktów, towarów i materiałów, w tym: | B12: 67645019 | C12: 67625893 | D12: 57682822 | E12: =C12-B12 -> -19126.02 | F12: =D12-C12 -> -9943071.1 | G12: =E12/B12 -> -0.00028274099 | H12: =F12/C12 -> -0.14703053 | I12: =C12/B12 -> 0.99971726 | J12: =D12/C12 -> 0.85296947
A13: III. Zysk (strata) brutto ze sprzedaży | B13: 18091572 | C13: 23217763 | D13: 12618538 | E13: =C13-B13 -> 5126191.9 | F13: =D13-C13 -> -10599225 | G13: =E13/B13 -> 0.28334696 | H13: =F13/C13 -> -0.45651361 | I13: =C13/B13 -> 1.283347 | J13: =D13/C13 -> 0.54348639
A14: V. Zysk (strata) z działalności operacyjnej | B14: 159356.88 | C14: 488859.82 | D14: -10954030 | E14: =C14-B14 -> 329502.94 | F14: =D14-C14 -> -11442890 | G14: =E14/B14 -> 2.0677045 | H14: =F14/C14 -> -23.407303 | I14: =C14/B14 -> 3.0677045 | J14: =D14/C14 -> -22.407303
A15: VI. Zysk (strata) brutto - przed opodatkowaniem | B15: -2600793.8 | C15: 1106098.2 | D15: -9833392.5 | E15: =C15-B15 -> 3706892 | F15: =D15-C15 -> -10939491 | G15: =E15/B15 -> -1.4252925 | H15: =F15/C15 -> -9.8901625 | I15: =C15/B15 -> -0.42529252 | J15: =D15/C15 -> -8.8901625
A16: C. Zysk (strata) netto za rok obrotowy | B16: -2020884.6 | C16: 236930.71 | D16: -10258889 | E16: =C16-B16 -> 2257815.3 | F16: =D16-C16 -> -10495820 | G16: =E16/B16 -> -1.1172411 | H16: =F16/C16 -> -44.29911 | I16: =C16/B16 -> -0.11724109 | J16: =D16/C16 -> -43.29911
A17: ELEMENTY CASH FLOW | B17: 2022 | C17: 2023 | D17: 2024 | E17: ZMIANA BEZW. 22-23 | F17: ZMIANA BEZW. 23-24 | G17: TEMPO ZMIAN 2022-23 | H17: TEAMPO ZMIAN 2023-24 | I17: WSKAŹ. DYNAMIKI 22-23 | J17: WSKAŹ DYNAMIKI 23-24
A18: III. Przepływy pieniężne netto z działalności operacyjnej (I+/-II) | B18: 1721795.2 | C18: 9447415.6 | D18: -8679563 | E18: =C18-B18 -> 7725620.4 | F18: =D18-C18 -> -18126979 | G18: =E18/B18 -> 4.4869567 | H18: =F18/C18 -> -1.9187235 | I18: =C18/B18 -> 5.4869567 | J18: =D18/C18 -> -0.91872353
A19: III. Przepływy pieniężne netto z działalności inwestycyjnej (I-II) | B19: 9159378.8 | C19: 6655523 | D19: -3076683.4 | E19: =C19-B19 -> -2503855.7 | F19: =D19-C19 -> -9732206.4 | G19: =E19/B19 -> -0.27336524 | H19: =F19/C19 -> -1.4622752 | I19: =C19/B19 -> 0.72663476 | J19: =D19/C19 -> -0.46227522
A20: III. Przepływy pieniężne netto z działalności finansowej (I-II) | B20: -10770303 | C20: -227714.38 | D20: -117971.47 | E20: =C20-B20 -> 10542588 | F20: =D20-C20 -> 109742.91 | G20: =E20/B20 -> -0.9788572 | H20: =F20/C20 -> -0.48193228 | I20: =C20/B20 -> 0.021142802 | J20: =D20/C20 -> 0.51806772
A21: D. PRZEPŁYWY PIENIĘŻNE NETTO RAZEM (A.III +/- B.III +/- C.III) | B21: 110871.31 | C21: 15875224 | D21: -11874218 | E21: =C21-B21 -> 15764353 | F21: =D21-C21 -> -27749442 | G21: =E21/B21 -> 142.18604 | H21: =F21/C21 -> -1.7479717 | I21: =C21/B21 -> 143.18604 | J21: =D21/C21 -> -0.74797166
E30: Analiza Pionowa | I30: ANALIZA POZIOMO - PIONOWA
A32: Pozycja | B32: stan 2022 | C32: stan 2023 | D32: stan 2024 | E32: Udział % w aktywach 2022 | F32: Udział % w aktywach 2023 | G32: Udział % w aktywach 2024 | I32: REGUŁA | J32: 2022 | K32: 2023 | L32: 2024
A33: A. Aktywa trwałe | B33: 31211272 | C33: 30390474 | D33: 24310206 | E33: =B33/$B$54 -> 0.43251378 | F33: =C33/$C$54 -> 0.42488977 | G33: =D33/$D$54 -> 0.46477083 | I33: Złota Reguła Bilansowa | J33: =B6/B3 -> 1.5286701 | K33: =C6/C3 -> 1.5777533 | L33: =D6/D3 -> 1.2696495
A34: 1. Wartość firmy | B34: 184193.99 | C34: 184193.99 | D34: 184193.99 | E34: =B34/$B$54 -> 0.0025524893 | F34: =C34/$C$54 -> 0.0025752196 | G34: =D34/$D$54 -> 0.0035214837 | I34: Srebrna Reguła Bilansowa | J34: =(B6+B7)/B3 -> 1.719694 | K34: =(C6+C7)/C3 -> 1.7654686 | L34: =(D6+D7)/D3 -> 1.4911848
A35: 2. Inne wartości niematerialne | B35: 4446486.5 | C35: 4406627.9 | D35: 8500781.2 | E35: =B35/$B$54 -> 0.061617696 | F35: =C35/$C$54 -> 0.061609146 | G35: =D35/$D$54 -> 0.16252084
A36: 3. Rzeczowe aktywa trwałe | B36: 16237944 | C36: 15044999 | D36: 14156555 | E36: =B36/$B$54 -> 0.22501917 | F36: =C36/$C$54 -> 0.21034441 | G36: =D36/$D$54 -> 0.27064985
A37: 4. Nieruchomości inwestycyjne | B37: - | C37: - | D37: - | E37: - | F37: - | G37: -
A38: 5. Należności długoterminowe | B38: 42602.34 | C38: 881125.73 | D38: 410947.73 | E38: =B38/$B$54 -> 0.00059036681 | F38: =C38/$C$54 -> 0.012319035 | G38: =D38/$D$54 -> 0.0078566392
A39: 6. Inwestycje w jednostkach podporządkowanych | B39: 8376521 | C39: 8498239 | D39: 0 | E39: =B39/$B$54 -> 0.1160786 | F39: =C39/$C$54 -> 0.11881404 | G39: =D39/$D$54 -> 0
A40: 7. Aktywa finansowe | B40: 400000 | C40: 400000 | D40: 400000 | E40: =B40/$B$54 -> 0.0055430459 | F40: =C40/$C$54 -> 0.0055924074 | G40: =D40/$D$54 -> 0.0076473367
A41: 8. Aktywa z tytułu podatku odroczonego | B41: 1523524 | C41: 975287.92 | D41: 657728.27 | E41: =B41/$B$54 -> 0.021112409 | F41: =C41/$C$54 -> 0.013635518 | G41: =D41/$D$54 -> 0.012574674
A42: 9. Inne rozliczenia międzyokresowe | B42: - | C42: - | D42: - | E42: - | F42: - | G42: -
A43: B. Aktywa obrotowe | B43: 40951220 | C43: 41135074 | D43: 27995585 | E43: =B43/$B$54 -> 0.56748622 | F43: =C43/$C$54 -> 0.57511023 | G43: =D43/$D$54 -> 0.53522917 | I43: WSTEPNA ANALIZA PP.
A44: 1. Zapasy | B44: 2912656.1 | C44: 1535369.1 | D44: 1522500.1 | E44: =B44/$B$54 -> 0.040362465 | F44: =C44/$C$54 -> 0.021466024 | G44: =D44/$D$54 -> 0.029107677
A45: 2. Należności z tytułu dostaw i usług | B45: 18142688 | C45: 12390084 | D45: 14492916 | E45: =B45/$B$54 -> 0.25141438 | F45: =C45/$C$54 -> 0.173226 | G45: =D45/$D$54 -> 0.27708051 | I45: ROK | J45: Działalność OP | K45: INW | L45: FIN
A46: 3. Aktywa z tytułu umów z klientami | B46: 3124218.4 | C46: 2267227.2 | D46: 3207419.3 | E46: =B46/$B$54 -> 0.043294215 | F46: =C46/$C$54 -> 0.031698145 | G46: =D46/$D$54 -> 0.061320539 | I46: 2022 | J46: + | K46: - | L46: -
A47: 4. Należności pozostałe | B47: 116295 | C47: 57104.25 | D47: 363887.9 | E47: =B47/$B$54 -> 0.0016115713 | F47: =C47/$C$54 -> 0.00079837557 | G47: =D47/$D$54 -> 0.0069569332 | I47: 2023 | J47: + | K47: - | L47: -
A48: 5. Należności z tytułu podatku dochodowego od osób prawnych | B48: - | C48: - | D48: - | E48: - | F48: - | G48: - | I48: 2024 | J48: - | K48: + | L48: -
A49: 6. Należności z tytułu pozostałych podatków, dotacji, ceł, ubezpieczeń | B49: 277813.45 | C49: 271073 | D49: 203760.13 | E49: =B49/$B$54 -> 0.0038498317 | F49: =C49/$C$54 -> 0.0037898766 | G49: =D49/$D$54 -> 0.0038955558
...

Sheet analiza wskaźnikowa
A1: Typ wskaźnika | C1: Nazwa wskaźnika | D1: Wzór | E1: Mediana sektora 2023 (dział 62) | F1: OPTeam 2022 | G1: OPTeam 2023 | H1: OPTeam 2024 | J1: Wniosek
A3: Wskaźniki rentowności | C3: Rentowność operacyjna aktywów | D3: wynik z działalności operacyjnej * 100/średnioroczny stan aktywów ogółem | E3: 12.82 | G3: =('RZIS & CASHFLOW & BILANS'!E75*100*2)/('RZIS & CASHFLOW & BILANS'!D26+'RZIS & CASHFLOW & BILANS'!E26) -> 0.68044609 | H3: =('RZIS & CASHFLOW & BILANS'!F75*100*2)/('RZIS & CASHFLOW & BILANS'!E26+'RZIS & CASHFLOW & BILANS'!F26) -> -17.691854 | J3: Destrukcja kapitału własnego i brak atrakcyjności dla inwestorów na tle sektora (mediana 20,06%).
C4: Rentowność kapitału własnego | D4: wynik netto * 100/średnioroczny stan kapitału własnego | E4: 20.06 | G4: =('RZIS & CASHFLOW & BILANS'!E81*100*2)/('RZIS & CASHFLOW & BILANS'!D32+'RZIS & CASHFLOW & BILANS'!E32) -> 0.49535794 | H4: =('RZIS & CASHFLOW & BILANS'!F81*100*2)/('RZIS & CASHFLOW & BILANS'!E32+'RZIS & CASHFLOW & BILANS'!F32) -> -26.033127 | J4: Skrajna nieefektywność majątku, który zamiast zysków generuje straty operacyjne.
C5: Rentowność netto | D5: wynik netto * 100/przychody ogółem | E5: 5.26 | F5: ='RZIS & CASHFLOW & BILANS'!D84*100/'RZIS & CASHFLOW & BILANS'!D63 -> -2.3570853 | G5: ='RZIS & CASHFLOW & BILANS'!E84*100/'RZIS & CASHFLOW & BILANS'!E63 -> 0.26081151 | H5: ='RZIS & CASHFLOW & BILANS'!F84*100/'RZIS & CASHFLOW & BILANS'!F63 -> -14.592732 | J5: Każda złotówka przychodu powiększa stratę netto, co wskazuje na całkowitą nierentowność sprzedaży
C6: Rentowność sprzedaży | D6: wynik ze sprzedaży * 100/przychody netto ze sprzedaży produktów towarów i materiałów | E6: 6.32 | F6: ='RZIS & CASHFLOW & BILANS'!D72*100/'RZIS & CASHFLOW & BILANS'!D63 -> 0.020575987 | G6: ='RZIS & CASHFLOW & BILANS'!E72*100/'RZIS & CASHFLOW & BILANS'!E63 -> 0.19805382 | H6: ='RZIS & CASHFLOW & BILANS'!F72*100/'RZIS & CASHFLOW & BILANS'!F63 -> -16.241116 | J6: Koszty operacyjne drastycznie przewyższają marże generowane na usługach IT.
C7: Rentowność ekonomiczna sprzedaży | D7: (wynik z działalności operacyjnej + amortyzacja) * 100/(przychody ze sprzedaży produktów, towarów i materiałów + pozostałe przychody operacyjne) | E7: 7.88 | F7: =('RZIS & CASHFLOW & BILANS'!D75+'RZIS & CASHFLOW & BILANS'!D93)*100/('RZIS & CASHFLOW & BILANS'!D63+'RZIS & CASHFLOW & BILANS'!D73) -> 3.035459 | G7: =('RZIS & CASHFLOW & BILANS'!E75+'RZIS & CASHFLOW & BILANS'!E93)*100/('RZIS & CASHFLOW & BILANS'!E63+'RZIS & CASHFLOW & BILANS'!E73) -> 3.7902301 | H7: =('RZIS & CASHFLOW & BILANS'!F75+'RZIS & CASHFLOW & BILANS'!F93)*100/('RZIS & CASHFLOW & BILANS'!F63+'RZIS & CASHFLOW & BILANS'!F73) -> -6.8980643
A8: Wskaźniki płynności finansowej | C8: Płynność bieżąca (wcześniej: płynność finansowa I stopnia) | D8: aktywa obrotowe ogółem (bez należności z tytułu dostaw i usług o okresie spłaty powyżej 12 mies.)/zobowiązania krótkoterminowe(bez zobowiązaniń z tytułu dostaw i usług o okresie wymagalności powyżej 12 mies) | E8: 2.73 | F8: ='RZIS & CASHFLOW & BILANS'!D15/'RZIS & CASHFLOW & BILANS'!D48 -> 2.2149377 | G8: ='RZIS & CASHFLOW & BILANS'!E15/'RZIS & CASHFLOW & BILANS'!E48 -> 2.3016335 | H8: ='RZIS & CASHFLOW & BILANS'!F15/'RZIS & CASHFLOW & BILANS'!F48 -> 1.7437536 | J8: Silny spadek marginesu bezpieczeństwa i utrata dystansu do średniej branżowej
C9: Płynność szybka (wcześniej płynność finansowa II stopnia) | D9: aktywa obrotowe ogółem (bez należności z tytułu dostaw i usług o okresie spłaty powyżej 12 mies.) - zapasy - krótkoterminowe rozliczenia międzyokresowe/zobowiązania krótkoterminowe(bez zobowiązaniń z tytułu dostaw i usług o okresie wymagalności powyżej 12 mies) | E9: 2.48 | F9: =('RZIS & CASHFLOW & BILANS'!D15-'RZIS & CASHFLOW & BILANS'!D16-'RZIS & CASHFLOW & BILANS'!D24)/'RZIS & CASHFLOW & BILANS'!D48 -> 2.0260659 | G9: =('RZIS & CASHFLOW & BILANS'!E15-'RZIS & CASHFLOW & BILANS'!E16-'RZIS & CASHFLOW & BILANS'!E24)/'RZIS & CASHFLOW & BILANS'!E48 -> 2.1838811 | H9: =('RZIS & CASHFLOW & BILANS'!F15-'RZIS & CASHFLOW & BILANS'!F16-'RZIS & CASHFLOW & BILANS'!F24)/'RZIS & CASHFLOW & BILANS'!F48 -> 1.6061388 | J9: Gwałtowny trend spadkowy r/r sygnalizuje realne ryzyko problemów płatniczych.
C10: Płynność gotówkowa (wcześniej: płynność finansowa III stopnia) | D10: inwestycje krótkoterminowe/zobowiązania krótkoterminowe(bez zobowiązań z tytułu dostaw i usług o okresie wymagalności powyżej 12 mies) | E10: 1 | F10: =('RZIS & CASHFLOW & BILANS'!D22+'RZIS & CASHFLOW & BILANS'!D23)/'RZIS & CASHFLOW & BILANS'!D48 -> 0.85448182 | G10: =('RZIS & CASHFLOW & BILANS'!E22+'RZIS & CASHFLOW & BILANS'!E23)/'RZIS & CASHFLOW & BILANS'!E48 -> 1.3453971 | H10: =('RZIS & CASHFLOW & BILANS'!F22+'RZIS & CASHFLOW & BILANS'!F23)/'RZIS & CASHFLOW & BILANS'!F48 -> 0.46828577 | J10: Firma może spłacić natychmiast mniej niż połowę pilnych długów.
A11: Wskaźniki sprawności działania | C11: Spływ należności | D11: średnioroczny stan ogółu należności z tytułu dostaw i usług * 365/przychody ze sprzedaży produktów, towarów i materiałów | E11: 44.64 | G11: =('RZIS & CASHFLOW & BILANS'!D17+'RZIS & CASHFLOW & BILANS'!E17)*365/(2*'RZIS & CASHFLOW & BILANS'!E63) -> 61.33869 | H11: =('RZIS & CASHFLOW & BILANS'!E17+'RZIS & CASHFLOW & BILANS'!F17)*365/(2*'RZIS & CASHFLOW & BILANS'!F63) -> 69.787376 | J11: Skrajna nieefektywność windykacji; pieniądze są zamrożone u klientów o 25 dni dłużej niż u konkurencji.
C12: Spłata zobowiązań | D12: średnioroczny stan ogółu zobowiązań z tytułu dostaw i usług * 365/przychody ze sprzedaży produktów, towarów i materiałów | E12: 19.01 | G12: =('RZIS & CASHFLOW & BILANS'!D51+'RZIS & CASHFLOW & BILANS'!E51)*365/(2*'RZIS & CASHFLOW & BILANS'!E63) -> 40.430728 | H12: =('RZIS & CASHFLOW & BILANS'!E51+'RZIS & CASHFLOW & BILANS'!F51)*365/(2*'RZIS & CASHFLOW & BILANS'!F63) -> 46.774081 | J12: Wymuszone kredytowanie się kosztem dostawców w celu łatania luki w płynności.
C13: Szybkość obrotu zapasów | D13: średnioroczny stan zapasów * 365/przychody ze sprzedaży produktów, towarów i materiałów | E13: 7.37 | G13: =('RZIS & CASHFLOW & BILANS'!D16+'RZIS & CASHFLOW & BILANS'!E16)*365/(2*'RZIS & CASHFLOW & BILANS'!E63) -> 8.9358424 | H13: =('RZIS & CASHFLOW & BILANS'!E16+'RZIS & CASHFLOW & BILANS'!F16)*365/(2*'RZIS & CASHFLOW & BILANS'!F63) -> 7.9381271 | J13: Efektywność zarządzania zapasami pozostaje na dobrym poziomie
A14: Wskaźniki zadłużenia | C14: Pokrycie aktywów trwałych kapitałem własnym i rezerwami długoterminowymi | D14: kapitał własny + rezerwy długoterminowe/aktywa trwałe + należności z tytułu dostaw i usług o okresie spłaty powyżej 12 mies. | E14: 3.2 | F14: =('RZIS & CASHFLOW & BILANS'!D32+'RZIS & CASHFLOW & BILANS'!D40)/'RZIS & CASHFLOW & BILANS'!D5 -> 1.719694 | G14: =('RZIS & CASHFLOW & BILANS'!E32+'RZIS & CASHFLOW & BILANS'!E40)/'RZIS & CASHFLOW & BILANS'!E5 -> 1.7654686 | H14: =('RZIS & CASHFLOW & BILANS'!F32+'RZIS & CASHFLOW & BILANS'!F40)/'RZIS & CASHFLOW & BILANS'!F5 -> -0.089690944 | J14: Majątek trwały jest w pełni finansowany bezpiecznym kapitałem stałym, jednak wynik jest znacznie niższy od mediany sektora
C15: Trwałość struktury finansowania | D15: kapitał własny + rezerwy długoterminowe + zobowiązania długoterminowe(łącznie z zobowiązaniami z tytułu dostaw i usług powyżej 12 mies)/aktywa ogółem | E15: 0.73 | F15: =('RZIS & CASHFLOW & BILANS'!D32+'RZIS & CASHFLOW & BILANS'!D40)/'RZIS & CASHFLOW & BILANS'!D26 -> 0.74379134 | G15: =('RZIS & CASHFLOW & BILANS'!E32+'RZIS & CASHFLOW & BILANS'!E40)/'RZIS & CASHFLOW & BILANS'!E26 -> 0.75012954 | H15: =('RZIS & CASHFLOW & BILANS'!F32+'RZIS & CASHFLOW & BILANS'!F40)/'RZIS & CASHFLOW & BILANS'!F26 -> 0.69305917 | J15: Kapitał stały nie zapewnia już wystarczającego oparcia dla majątku firmy.
C16: Ogólne zadłużenie | D16: zobowiązania i rezerwy na zobowiązania*100/aktywa ogółem | E16: 29.78 | F16: =('RZIS & CASHFLOW & BILANS'!D40+'RZIS & CASHFLOW & BILANS'!D48)*100/'RZIS & CASHFLOW & BILANS'!D26 -> 33.882912 | G16: =('RZIS & CASHFLOW & BILANS'!E40+'RZIS & CASHFLOW & BILANS'!E48)*100/'RZIS & CASHFLOW & BILANS'!E26 -> 32.962878 | H16: =('RZIS & CASHFLOW & BILANS'!F40+'RZIS & CASHFLOW & BILANS'!F48)*100/'RZIS & CASHFLOW & BILANS'!F26 -> 40.990394 | J16: Udział długu w majątku jest o ponad 10 pkt proc. wyższy niż mediana sektora.

Sheet wnioski

Sheet Ocena
A1: Kryterium oceny | B1: Opis | C1: Punkty (1-5) | D1: Komentarz
A2: Wskaźniki | B2: Poprawne formuły i ustalone wartości | C2: 5 | D2: Poprawnie wyliczone wskaźniki (>10)
A3: Wnioski cząstkowe | B3: Poprawna interpretacja wyników, porównanie branżowe | C3: 4 | D3: Krótkie lecz na temat, aczkolwiek czasem bezpodstawne
A4: Wizualizacje | B4: Czytelność i jakość merytoryczna wykresów, tabel, rysunków | C4: 5 | D4: Czytelne i estetyczne tabele i wykresy
A5: Wnioski końcowe i rekomendacje | B5: Wskazanie problemu i praktyczne sugestie | C5: 4 | D5: Dobre wnioskowanie jedank brak rekomendacji
A6: Ocena końcowa | B6: Suma uzyskanych punktów | C6: 18 | D6: Ocena : 5.0
C7: =C6/20 -> 0.9
